Bad Request: /api/psf/load_image/
Internal Server Error: /api/network/load_image/
Traceback (most recent call last):
  File "/usr/local/lib/python3.9/site-packages/django/core/handlers/exception.py", line 47, in inner
    response = get_response(request)
  File "/usr/local/lib/python3.9/site-packages/django/core/handlers/base.py", line 167, in _get_response
    callback, callback_args, callback_kwargs = self.resolve_request(request)
  File "/usr/local/lib/python3.9/site-packages/django/core/handlers/base.py", line 290, in resolve_request
    resolver_match = resolver.resolve(request.path_info)
  File "/usr/local/lib/python3.9/site-packages/django/urls/resolvers.py", line 560, in resolve
    for pattern in self.url_patterns:
  File "/usr/local/lib/python3.9/site-packages/django/utils/functional.py", line 48, in __get__
    res = instance.__dict__[self.name] = self.func(instance)
  File "/usr/local/lib/python3.9/site-packages/django/urls/resolvers.py", line 602, in url_patterns
    patterns = getattr(self.urlconf_module, "urlpatterns", self.urlconf_module)
  File "/usr/local/lib/python3.9/site-packages/django/utils/functional.py", line 48, in __get__
    res = instance.__dict__[self.name] = self.func(instance)
  File "/usr/local/lib/python3.9/site-packages/django/urls/resolvers.py", line 595, in urlconf_module
    return import_module(self.urlconf_name)
  File "/usr/local/lib/python3.9/importlib/__init__.py", line 127, in import_module
    return _bootstrap._gcd_import(name[level:], package, level)
  File "<frozen importlib._bootstrap>", line 1030, in _gcd_import
  File "<frozen importlib._bootstrap>", line 1007, in _find_and_load
  File "<frozen importlib._bootstrap>", line 986, in _find_and_load_unlocked
  File "<frozen importlib._bootstrap>", line 680, in _load_unlocked
  File "<frozen importlib._bootstrap_external>", line 850, in exec_module
  File "<frozen importlib._bootstrap>", line 228, in _call_with_frames_removed
  File "/app/backend/urls.py", line 19, in <module>
    from api import views
  File "/app/api/views.py", line 11, in <module>
    from backend.engine.cnn_engine import process_cnn
ModuleNotFoundError: No module named 'backend.engine'
Bad Request: /api/network/load_image/
Bad Request: /api/network/processing/
Bad Request: /api/network/processing/
Internal Server Error: /api/network/load_image/
Traceback (most recent call last):
  File "/usr/local/lib/python3.9/site-packages/django/core/handlers/exception.py", line 47, in inner
    response = get_response(request)
  File "/usr/local/lib/python3.9/site-packages/django/core/handlers/base.py", line 167, in _get_response
    callback, callback_args, callback_kwargs = self.resolve_request(request)
  File "/usr/local/lib/python3.9/site-packages/django/core/handlers/base.py", line 290, in resolve_request
    resolver_match = resolver.resolve(request.path_info)
  File "/usr/local/lib/python3.9/site-packages/django/urls/resolvers.py", line 560, in resolve
    for pattern in self.url_patterns:
  File "/usr/local/lib/python3.9/site-packages/django/utils/functional.py", line 48, in __get__
    res = instance.__dict__[self.name] = self.func(instance)
  File "/usr/local/lib/python3.9/site-packages/django/urls/resolvers.py", line 602, in url_patterns
    patterns = getattr(self.urlconf_module, "urlpatterns", self.urlconf_module)
  File "/usr/local/lib/python3.9/site-packages/django/utils/functional.py", line 48, in __get__
    res = instance.__dict__[self.name] = self.func(instance)
  File "/usr/local/lib/python3.9/site-packages/django/urls/resolvers.py", line 595, in urlconf_module
    return import_module(self.urlconf_name)
  File "/usr/local/lib/python3.9/importlib/__init__.py", line 127, in import_module
    return _bootstrap._gcd_import(name[level:], package, level)
  File "<frozen importlib._bootstrap>", line 1030, in _gcd_import
  File "<frozen importlib._bootstrap>", line 1007, in _find_and_load
  File "<frozen importlib._bootstrap>", line 986, in _find_and_load_unlocked
  File "<frozen importlib._bootstrap>", line 680, in _load_unlocked
  File "<frozen importlib._bootstrap_external>", line 850, in exec_module
  File "<frozen importlib._bootstrap>", line 228, in _call_with_frames_removed
  File "/app/backend/urls.py", line 19, in <module>
    from api import views
  File "/app/api/views.py", line 11, in <module>
    from engine.cnn_engine import process_cnn
  File "/app/engine/cnn_engine.py", line 2, in <module>
    from models import CNNParameters
ModuleNotFoundError: No module named 'models'
Internal Server Error: /api/network/processing/
Traceback (most recent call last):
  File "/usr/local/lib/python3.9/site-packages/django/core/handlers/exception.py", line 47, in inner
    response = get_response(request)
  File "/usr/local/lib/python3.9/site-packages/django/core/handlers/base.py", line 181, in _get_response
    response = wrapped_callback(request, *callback_args, **callback_kwargs)
  File "/usr/local/lib/python3.9/site-packages/django/views/decorators/csrf.py", line 54, in wrapped_view
    return view_func(*args, **kwargs)
  File "/app/api/views.py", line 108, in cnn_processing
    processed_image = process_cnn(cnn_param)
UnboundLocalError: local variable 'cnn_param' referenced before assignment
Internal Server Error: /api/network/processing/
Traceback (most recent call last):
  File "/usr/local/lib/python3.9/site-packages/django/core/handlers/exception.py", line 47, in inner
    response = get_response(request)
  File "/usr/local/lib/python3.9/site-packages/django/core/handlers/base.py", line 181, in _get_response
    response = wrapped_callback(request, *callback_args, **callback_kwargs)
  File "/usr/local/lib/python3.9/site-packages/django/views/decorators/csrf.py", line 54, in wrapped_view
    return view_func(*args, **kwargs)
  File "/app/api/views.py", line 108, in cnn_processing
    cnn_param = CNNParameters(start_image=cached_object, maximize_intensity=maximize_intensity, gaussian_blur=gaussian_blur, result=processed_image)
UnboundLocalError: local variable 'processed_image' referenced before assignment
Internal Server Error: /api/network/processing/
Traceback (most recent call last):
  File "/usr/local/lib/python3.9/site-packages/PIL/Image.py", line 2979, in open
    fp.seek(0)
AttributeError: 'dict' object has no attribute 'seek'

During handling of the above exception, another exception occurred:

Traceback (most recent call last):
  File "/usr/local/lib/python3.9/site-packages/django/core/handlers/exception.py", line 47, in inner
    response = get_response(request)
  File "/usr/local/lib/python3.9/site-packages/django/core/handlers/base.py", line 181, in _get_response
    response = wrapped_callback(request, *callback_args, **callback_kwargs)
  File "/usr/local/lib/python3.9/site-packages/django/views/decorators/csrf.py", line 54, in wrapped_view
    return view_func(*args, **kwargs)
  File "/app/api/views.py", line 109, in cnn_processing
    processed_image = process_cnn(cnn_param)
  File "/app/engine/cnn_engine.py", line 6, in process_cnn
    img = Image.open(cnn_param.start_image)
  File "/usr/local/lib/python3.9/site-packages/PIL/Image.py", line 2981, in open
    fp = io.BytesIO(fp.read())
AttributeError: 'dict' object has no attribute 'read'
Internal Server Error: /api/network/processing/
Traceback (most recent call last):
  File "/usr/local/lib/python3.9/site-packages/PIL/Image.py", line 2979, in open
    fp.seek(0)
AttributeError: 'dict' object has no attribute 'seek'

During handling of the above exception, another exception occurred:

Traceback (most recent call last):
  File "/usr/local/lib/python3.9/site-packages/django/core/handlers/exception.py", line 47, in inner
    response = get_response(request)
  File "/usr/local/lib/python3.9/site-packages/django/core/handlers/base.py", line 181, in _get_response
    response = wrapped_callback(request, *callback_args, **callback_kwargs)
  File "/usr/local/lib/python3.9/site-packages/django/views/decorators/csrf.py", line 54, in wrapped_view
    return view_func(*args, **kwargs)
  File "/app/api/views.py", line 109, in cnn_processing
    processed_image = process_cnn(cnn_param)
  File "/app/engine/cnn_engine.py", line 5, in process_cnn
    img = Image.open(cnn_param.start_image)
  File "/usr/local/lib/python3.9/site-packages/PIL/Image.py", line 2981, in open
    fp = io.BytesIO(fp.read())
AttributeError: 'dict' object has no attribute 'read'
Internal Server Error: /api/network/processing/
Traceback (most recent call last):
  File "/usr/local/lib/python3.9/site-packages/django/core/handlers/exception.py", line 47, in inner
    response = get_response(request)
  File "/usr/local/lib/python3.9/site-packages/django/core/handlers/base.py", line 181, in _get_response
    response = wrapped_callback(request, *callback_args, **callback_kwargs)
  File "/usr/local/lib/python3.9/site-packages/django/views/decorators/csrf.py", line 54, in wrapped_view
    return view_func(*args, **kwargs)
  File "/app/api/views.py", line 109, in cnn_processing
    processed_image = process_cnn(cnn_param)
  File "/app/engine/cnn_engine.py", line 5, in process_cnn
    img = Image.open(cnn_param.start_image.data)
AttributeError: 'dict' object has no attribute 'data'
Internal Server Error: /api/network/processing/
Traceback (most recent call last):
  File "/usr/local/lib/python3.9/site-packages/django/core/handlers/exception.py", line 47, in inner
    response = get_response(request)
  File "/usr/local/lib/python3.9/site-packages/django/core/handlers/base.py", line 181, in _get_response
    response = wrapped_callback(request, *callback_args, **callback_kwargs)
  File "/usr/local/lib/python3.9/site-packages/django/views/decorators/csrf.py", line 54, in wrapped_view
    return view_func(*args, **kwargs)
  File "/app/api/views.py", line 116, in cnn_processing
    return JsonResponse(response_data)
  File "/usr/local/lib/python3.9/site-packages/django/http/response.py", line 605, in __init__
    data = json.dumps(data, cls=encoder, **json_dumps_params)
  File "/usr/local/lib/python3.9/json/__init__.py", line 234, in dumps
    return cls(
  File "/usr/local/lib/python3.9/json/encoder.py", line 199, in encode
    chunks = self.iterencode(o, _one_shot=True)
  File "/usr/local/lib/python3.9/json/encoder.py", line 257, in iterencode
    return _iterencode(o, 0)
  File "/usr/local/lib/python3.9/site-packages/django/core/serializers/json.py", line 105, in default
    return super().default(o)
  File "/usr/local/lib/python3.9/json/encoder.py", line 179, in default
    raise TypeError(f'Object of type {o.__class__.__name__} '
TypeError: Object of type TiffImageFile is not JSON serializable
Internal Server Error: /api/network/processing/
Traceback (most recent call last):
  File "/usr/local/lib/python3.9/site-packages/django/core/handlers/exception.py", line 47, in inner
    response = get_response(request)
  File "/usr/local/lib/python3.9/site-packages/django/core/handlers/base.py", line 181, in _get_response
    response = wrapped_callback(request, *callback_args, **callback_kwargs)
  File "/usr/local/lib/python3.9/site-packages/django/views/decorators/csrf.py", line 54, in wrapped_view
    return view_func(*args, **kwargs)
  File "/app/api/views.py", line 109, in cnn_processing
    processed_image = process_cnn(cnn_param)
  File "/app/engine/cnn_engine.py", line 7, in process_cnn
    image_data = base64.b64decode(cnn_param.start_image.data)
AttributeError: 'dict' object has no attribute 'data'
Internal Server Error: /api/network/processing/
Traceback (most recent call last):
  File "/usr/local/lib/python3.9/site-packages/django/core/handlers/exception.py", line 47, in inner
    response = get_response(request)
  File "/usr/local/lib/python3.9/site-packages/django/core/handlers/base.py", line 181, in _get_response
    response = wrapped_callback(request, *callback_args, **callback_kwargs)
  File "/usr/local/lib/python3.9/site-packages/django/views/decorators/csrf.py", line 54, in wrapped_view
    return view_func(*args, **kwargs)
  File "/app/api/views.py", line 109, in cnn_processing
    processed_image = process_cnn(cnn_param)
  File "/app/engine/cnn_engine.py", line 7, in process_cnn
    image_data = cnn_param.start_image.data
AttributeError: 'dict' object has no attribute 'data'
Internal Server Error: /api/network/processing/
Traceback (most recent call last):
  File "/usr/local/lib/python3.9/site-packages/django/core/handlers/exception.py", line 47, in inner
    response = get_response(request)
  File "/usr/local/lib/python3.9/site-packages/django/core/handlers/base.py", line 181, in _get_response
    response = wrapped_callback(request, *callback_args, **callback_kwargs)
  File "/usr/local/lib/python3.9/site-packages/django/views/decorators/csrf.py", line 54, in wrapped_view
    return view_func(*args, **kwargs)
  File "/app/api/views.py", line 109, in cnn_processing
    processed_image = process_cnn(cnn_param)
  File "/app/engine/cnn_engine.py", line 7, in process_cnn
    image_data = cnn_param.start_image.data
AttributeError: 'dict' object has no attribute 'data'
